Workbook

Sheet Dashboard
A1: SPSS Educator Dashboard — Hillcrest Middle School (50 students) | N1: Calc Engine
A3: Design : At-Risk Focus + Attendance Watch List | N3: =COUNTA('Student Data'!A2:A51) -> 50
A5: Total Students | C5: AT-RISK (Red+Yellow) | F5: GREEN - Satisfactory | H5: % Satisfactory | N5: =COUNTIF('Student Data'!J2:J51,"RED - Dual Risk") -> 8
A6: =N3 -> 50 | C6: =N8 -> 27 | F6: =N7 -> 23 | H6: =N9 -> 0.46 | N6: =COUNTIF('Student Data'!J2:J51,"YELLOW - Single Risk") -> 19
N7: =COUNTIF('Student Data'!J2:J51,"GREEN - Satisfactory") -> 23
N8: =N5+N6 -> 27
A9: students | C9: students | F9: students | H9: of roster | N9: =N7/N3 -> 0.46
A12: Risk Category Breakdown
A13: Category | B13: Students
A14: RED - Dual Risk | B14: =N5 -> 8
A15: YELLOW - Single Risk | B15: =N6 -> 19
A16: GREEN - Satisfactory | B16: =N7 -> 23
A19: Attendance Watch List — 8 Lowest
A20: Rank | B20: Student | C20: Attendance %
A21: 1 | B21: =INDEX('Student Data'!$B$2:$B$51,MATCH(SMALL('Student Data'!$R$2:$R$51,1),'Student Data'!$R$2:$R$51,0)) -> Selena Onyema | C21: =SMALL('Student Data'!$G$2:$G$51,1) -> 40.7
A22: 2 | B22: =INDEX('Student Data'!$B$2:$B$51,MATCH(SMALL('Student Data'!$R$2:$R$51,2),'Student Data'!$R$2:$R$51,0)) -> Isla Mbeki | C22: =SMALL('Student Data'!$G$2:$G$51,2) -> 43.7
A23: 3 | B23: =INDEX('Student Data'!$B$2:$B$51,MATCH(SMALL('Student Data'!$R$2:$R$51,3),'Student Data'!$R$2:$R$51,0)) -> Sadie Sundberg | C23: =SMALL('Student Data'!$G$2:$G$51,3) -> 45.9
A24: 4 | B24: =INDEX('Student Data'!$B$2:$B$51,MATCH(SMALL('Student Data'!$R$2:$R$51,4),'Student Data'!$R$2:$R$51,0)) -> Gavin Blackwood | C24: =SMALL('Student Data'!$G$2:$G$51,4) -> 46.3
A25: 5 | B25: =INDEX('Student Data'!$B$2:$B$51,MATCH(SMALL('Student Data'!$R$2:$R$51,5),'Student Data'!$R$2:$R$51,0)) -> Jamal Okwuosa | C25: =SMALL('Student Data'!$G$2:$G$51,5) -> 46.7
A26: 6 | B26: =INDEX('Student Data'!$B$2:$B$51,MATCH(SMALL('Student Data'!$R$2:$R$51,6),'Student Data'!$R$2:$R$51,0)) -> Ines Idrissi | C26: =SMALL('Student Data'!$G$2:$G$51,6) -> 48.3
A27: 7 | B27: =INDEX('Student Data'!$B$2:$B$51,MATCH(SMALL('Student Data'!$R$2:$R$51,7),'Student Data'!$R$2:$R$51,0)) -> Simone Rojas | C27: =SMALL('Student Data'!$G$2:$G$51,7) -> 55
A28: 8 | B28: =INDEX('Student Data'!$B$2:$B$51,MATCH(SMALL('Student Data'!$R$2:$R$51,8),'Student Data'!$R$2:$R$51,0)) -> Miles Reyes | C28: =SMALL('Student Data'!$G$2:$G$51,8) -> 57
A31: Weekly Risk Trend — Week 1 is live;
A32: Week | B32: Red | C32: Yellow | D32: Green
A33: Week 1 (current) | B33: =N5 -> 8 | C33: =N6 -> 19 | D33: =N7 -> 23
A34: Week 2 | B34: 9 | C34: 5 | D34: 36
A35: Week 3 | B35: 9 | C35: 6 | D35: 35
A36: Week 4 | B36: 11 | C36: 5 | D36: 34
A37: Week 5 | B37: 11 | C37: 4 | D37: 35
A38: Week 6 | B38: 11 | C38: 5 | D38: 34
A39: Week 7
A40: Week 8
A41: Week 9
A42: Week 10
A44: Interactive Filter Panel (pick from the dropdowns — KPIs below update instantly)
A46: Filter: Academic Status | C46: All
A47: Filter: Attendance Status | C47: All
A49: Filtered Risk Breakdown
A50: Category | B50: Students
A51: RED - Dual Risk | B51: =COUNTIFS('Student Data'!$H$2:$H$51,IF($C$46="All","*",$C$46),'Student Data'!$I$2:$I$51,IF($C$47="All","*",$C$47),'Student Data'!$J$2:$J$51,"RED - Dual Risk") -> 8
...

Sheet Student Data
A1: Student ID | B1: Name | C1: Test 1 | D1: Test 2 | E1: Test 3 | F1: Average | G1: Attendance % | H1: Academic Status | I1: Attendance Status | J1: Risk Category | R1: RankKey
A2: TR2-1001 | B2: Owen Marsh | C2: 31 | D2: 39 | E2: 32 | F2: =ROUND(AVERAGE(C2:E2),1) -> 34 | G2: 70.1 | H2: =IF(F2<60,"FAIL","PASS") -> FAIL | I2: =IF(G2<75,"FAIL","PASS") -> FAIL | J2: =IF(AND(H2="FAIL",I2="FAIL"),"RED - Dual Risk",IF(OR(H2="FAIL",I2="FAIL"),"YELLOW - Single Risk","GREEN - Satisfactory")) -> RED - Dual Risk | R2: =G2+(ROW()-1)/1000000 -> 70.100001
A3: TR2-1002 | B3: Ines Idrissi | C3: 50 | D3: 53 | E3: 48 | F3: =ROUND(AVERAGE(C3:E3),1) -> 50.3 | G3: 48.3 | H3: =IF(F3<60,"FAIL","PASS") -> FAIL | I3: =IF(G3<75,"FAIL","PASS") -> FAIL | J3: =IF(AND(H3="FAIL",I3="FAIL"),"RED - Dual Risk",IF(OR(H3="FAIL",I3="FAIL"),"YELLOW - Single Risk","GREEN - Satisfactory")) -> RED - Dual Risk | R3: =G3+(ROW()-1)/1000000 -> 48.300002
A4: TR2-1003 | B4: Malik Chaudhary | C4: 42 | D4: 44 | E4: 55 | F4: =ROUND(AVERAGE(C4:E4),1) -> 47 | G4: 83.8 | H4: =IF(F4<60,"FAIL","PASS") -> FAIL | I4: =IF(G4<75,"FAIL","PASS") -> PASS | J4: =IF(AND(H4="FAIL",I4="FAIL"),"RED - Dual Risk",IF(OR(H4="FAIL",I4="FAIL"),"YELLOW - Single Risk","GREEN - Satisfactory")) -> YELLOW - Single Risk | R4: =G4+(ROW()-1)/1000000 -> 83.800003
A5: TR2-1004 | B5: Ruby Winslow | C5: 79 | D5: 78 | E5: 81 | F5: =ROUND(AVERAGE(C5:E5),1) -> 79.3 | G5: 69.4 | H5: =IF(F5<60,"FAIL","PASS") -> PASS | I5: =IF(G5<75,"FAIL","PASS") -> FAIL | J5: =IF(AND(H5="FAIL",I5="FAIL"),"RED - Dual Risk",IF(OR(H5="FAIL",I5="FAIL"),"YELLOW - Single Risk","GREEN - Satisfactory")) -> YELLOW - Single Risk | R5: =G5+(ROW()-1)/1000000 -> 69.400004
A6: TR2-1005 | B6: Diego Barreto | C6: 75 | D6: 82 | E6: 63 | F6: =ROUND(AVERAGE(C6:E6),1) -> 73.3 | G6: 90.3 | H6: =IF(F6<60,"FAIL","PASS") -> PASS | I6: =IF(G6<75,"FAIL","PASS") -> PASS | J6: =IF(AND(H6="FAIL",I6="FAIL"),"RED - Dual Risk",IF(OR(H6="FAIL",I6="FAIL"),"YELLOW - Single Risk","GREEN - Satisfactory")) -> GREEN - Satisfactory | R6: =G6+(ROW()-1)/1000000 -> 90.300005
A7: TR2-1006 | B7: Nadia Kowalski | C7: 47 | D7: 47 | E7: 51 | F7: =ROUND(AVERAGE(C7:E7),1) -> 48.3 | G7: 94.1 | H7: =IF(F7<60,"FAIL","PASS") -> FAIL | I7: =IF(G7<75,"FAIL","PASS") -> PASS | J7: =IF(AND(H7="FAIL",I7="FAIL"),"RED - Dual Risk",IF(OR(H7="FAIL",I7="FAIL"),"YELLOW - Single Risk","GREEN - Satisfactory")) -> YELLOW - Single Risk | R7: =G7+(ROW()-1)/1000000 -> 94.100006
A8: TR2-1007 | B8: Caleb Njoroge | C8: 82 | D8: 82 | E8: 86 | F8: =ROUND(AVERAGE(C8:E8),1) -> 83.3 | G8: 79 | H8: =IF(F8<60,"FAIL","PASS") -> PASS | I8: =IF(G8<75,"FAIL","PASS") -> PASS | J8: =IF(AND(H8="FAIL",I8="FAIL"),"RED - Dual Risk",IF(OR(H8="FAIL",I8="FAIL"),"YELLOW - Single Risk","GREEN - Satisfactory")) -> GREEN - Satisfactory | R8: =G8+(ROW()-1)/1000000 -> 79.000007
A9: TR2-1008 | B9: Yasmin Vasquez | C9: 95 | D9: 82 | E9: 82 | F9: =ROUND(AVERAGE(C9:E9),1) -> 86.3 | G9: 77.8 | H9: =IF(F9<60,"FAIL","PASS") -> PASS | I9: =IF(G9<75,"FAIL","PASS") -> PASS | J9: =IF(AND(H9="FAIL",I9="FAIL"),"RED - Dual Risk",IF(OR(H9="FAIL",I9="FAIL"),"YELLOW - Single Risk","GREEN - Satisfactory")) -> GREEN - Satisfactory | R9: =G9+(ROW()-1)/1000000 -> 77.800008
A10: TR2-1009 | B10: Trevor Hartley | C10: 72 | D10: 97 | E10: 80 | F10: =ROUND(AVERAGE(C10:E10),1) -> 83 | G10: 75.4 | H10: =IF(F10<60,"FAIL","PASS") -> PASS | I10: =IF(G10<75,"FAIL","PASS") -> PASS | J10: =IF(AND(H10="FAIL",I10="FAIL"),"RED - Dual Risk",IF(OR(H10="FAIL",I10="FAIL"),"YELLOW - Single Risk","GREEN - Satisfactory")) -> GREEN - Satisfactory | R10: =G10+(ROW()-1)/1000000 -> 75.400009
A11: TR2-1010 | B11: Aaliyah Suarez | C11: 92 | D11: 84 | E11: 96 | F11: =ROUND(AVERAGE(C11:E11),1) -> 90.7 | G11: 99.5 | H11: =IF(F11<60,"FAIL","PASS") -> PASS | I11: =IF(G11<75,"FAIL","PASS") -> PASS | J11: =IF(AND(H11="FAIL",I11="FAIL"),"RED - Dual Risk",IF(OR(H11="FAIL",I11="FAIL"),"YELLOW - Single Risk","GREEN - Satisfactory")) -> GREEN - Satisfactory | R11: =G11+(ROW()-1)/1000000 -> 99.50001
A12: TR2-1011 | B12: Felix Ferreira | C12: 31 | D12: 37 | E12: 57 | F12: =ROUND(AVERAGE(C12:E12),1) -> 41.7 | G12: 65.6 | H12: =IF(F12<60,"FAIL","PASS") -> FAIL | I12: =IF(G12<75,"FAIL","PASS") -> FAIL | J12: =IF(AND(H12="FAIL",I12="FAIL"),"RED - Dual Risk",IF(OR(H12="FAIL",I12="FAIL"),"YELLOW - Single Risk","GREEN - Satisfactory")) -> RED - Dual Risk | R12: =G12+(ROW()-1)/1000000 -> 65.600011
A13: TR2-1012 | B13: Layla Adeyemi | C13: 76 | D13: 98 | E13: 91 | F13: =ROUND(AVERAGE(C13:E13),1) -> 88.3 | G13: 99 | H13: =IF(F13<60,"FAIL","PASS") -> PASS | I13: =IF(G13<75,"FAIL","PASS") -> PASS | J13: =IF(AND(H13="FAIL",I13="FAIL"),"RED - Dual Risk",IF(OR(H13="FAIL",I13="FAIL"),"YELLOW - Single Risk","GREEN - Satisfactory")) -> GREEN - Satisfactory | R13: =G13+(ROW()-1)/1000000 -> 99.000012
... A51: TR2-1050 | B51: Kayla Brennan | C51: 76 | D51: 95 | E51: 87 | F51: =ROUND(AVERAGE(C51:E51),1) -> 86 | G51: 83.1 | H51: =IF(F51<60,"FAIL","PASS") -> PASS | I51: =IF(G51<75,"FAIL","PASS") -> PASS | J51: =IF(AND(H51="FAIL",I51="FAIL"),"RED - Dual Risk",IF(OR(H51="FAIL",I51="FAIL"),"YELLOW - Single Risk","GREEN - Satisfactory")) -> GREEN - Satisfactory | R51: =G51+(ROW()-1)/1000000 -> 83.10005

Sheet README
A1: SPSS Educator Dashboard — Hillcrest Middle School (50 students)
A3: Excel + Orange SPSS workflow.
A5: Rows: 50 fictional students, randomly generated.
A7: Thresholds (same rule definitions as the assignment):
A8: - Academic Threshold: Average of Test 1-3 < 60% => FAIL
A9: - Attendance Threshold: Attendance % < 75% => FAIL
A11: Columns F (Average), H (Academic Status), I (Attendance Status), and J (Risk Category)
A12: are LIVE FORMULAS - replacing columns C:E and G with real data recalculates everything.
A14: IMPORTANT - Orange setup: when you load this into Orange, set Academic Status and
A15: Attendance Status to META (not Feature) in the File widget. Leaving them as Features
A16: causes the Decision Tree to see the answer directly and score a meaningless 1.000.
